// Copyright 2018-2025 the Deno authors. MIT license.
import { assertEquals, assertRejects } from "@std/assert";
import { abortable } from "./abortable.ts";
import { delay } from "./delay.ts";

Deno.test("abortable() handles resolved promise", async () => {
  const c = new AbortController();
  const { promise, resolve } = Promise.withResolvers<string>();
  setTimeout(() => resolve("Hello"), 10);
  const result = await abortable(promise, c.signal);
  assertEquals(result, "Hello");
});

Deno.test("abortable() handles rejected promise", async () => {
  const c = new AbortController();
  const { promise, reject } = Promise.withResolvers<string>();
  setTimeout(() => reject(new Error("This is my error")), 10);
  await assertRejects(
    () => abortable(promise, c.signal),
    Error,
    "This is my error",
  );
});

Deno.test("abortable() handles resolved promise with aborted signal after delay", async () => {
  const c = new AbortController();
  const { promise, resolve } = Promise.withResolvers<string>();
  setTimeout(() => resolve("Hello"), 10);
  setTimeout(() => c.abort(), 5);
  const error = await assertRejects(
    () => abortable(promise, c.signal),
    DOMException,
    "The signal has been aborted",
  );
  assertEquals(error.name, "AbortError");
  await delay(5); // wait for the promise to resolve
});

Deno.test("abortable() handles rejected promise with aborted signal after delay", async () => {
  const c = new AbortController();
  const { promise, reject } = Promise.withResolvers<string>();
  setTimeout(() => reject(new Error("This is my error")), 10);
  setTimeout(() => c.abort(), 5);
  const error = await assertRejects(
    () => abortable(promise, c.signal),
    DOMException,
    "The signal has been aborted",
  );
  assertEquals(error.name, "AbortError");
  await delay(5); // wait for the promise to reject
  // an uncaught error should not occur
});

Deno.test("abortable() handles resolved promise with aborted signal after delay with reason", async () => {
  const c = new AbortController();
  const { promise, resolve } = Promise.withResolvers<string>();
  setTimeout(() => resolve("Hello"), 10);
  setTimeout(() => c.abort(new Error("This is my reason")), 5);
  await assertRejects(
    () => abortable(promise, c.signal),
    Error,
    "This is my reason",
  );
  await delay(5); // wait for the promise to resolve
});

Deno.test("abortable() handles resolved promise with already aborted signal", async () => {
  const c = new AbortController();
  const { promise, resolve } = Promise.withResolvers<string>();
  setTimeout(() => resolve("Hello"), 10);
  c.abort();
  const error = await assertRejects(
    async () => {
      await abortable(promise, c.signal);
    },
    DOMException,
    "The signal has been aborted",
  );
  assertEquals(error.name, "AbortError");
  await delay(10); // wait for the promise to resolve
});

Deno.test("abortable() handles rejected promise with already aborted signal", async () => {
  const c = new AbortController();
  const { promise, reject } = Promise.withResolvers<string>();
  setTimeout(() => reject(new Error("This is my error")), 10);
  c.abort();
  const error = await assertRejects(
    async () => {
      await abortable(promise, c.signal);
    },
    DOMException,
    "The signal has been aborted",
  );
  assertEquals(error.name, "AbortError");
  await delay(10); // wait for the promise to reject
  // an uncaught error should not occur
});

Deno.test("abortable() handles resolved promise with already aborted signal and reason", async () => {
  const c = new AbortController();
  const { promise, resolve } = Promise.withResolvers<string>();
  setTimeout(() => resolve("Hello"), 10);
  c.abort(new Error("This is my reason"));
  await assertRejects(
    () => abortable(promise, c.signal),
    Error,
    "This is my reason",
  );
  await delay(10); // wait for the promise to resolve
});

Deno.test("abortable.AsyncIterable()", async () => {
  const c = new AbortController();
  const { promise, resolve } = Promise.withResolvers<string>();
  setTimeout(() => resolve("My promise resolved"), 10);
  const a = async function* () {
    yield "Hello";
    await promise;
    yield "World";
  };
  const items = await Array.fromAsync(abortable(a(), c.signal));
  assertEquals(items, ["Hello", "World"]);
});

Deno.test("abortable.AsyncIterable() handles aborted signal after delay", async () => {
  const c = new AbortController();
  const { promise, resolve } = Promise.withResolvers<string>();
  setTimeout(() => resolve("My promise resolved"), 10);
  const a = async function* () {
    yield "Hello";
    await promise;
    yield "World";
  };
  setTimeout(() => c.abort(), 5);
  const items: string[] = [];
  const error = await assertRejects(
    async () => {
      for await (const item of abortable(a(), c.signal)) {
        items.push(item);
      }
    },
    DOMException,
    "The signal has been aborted",
  );
  assertEquals(error.name, "AbortError");
  assertEquals(items, ["Hello"]);
});

Deno.test("abortable.AsyncIterable() handles already aborted signal", async () => {
  const c = new AbortController();
  const { promise, resolve } = Promise.withResolvers<string>();
  setTimeout(() => resolve("My promise resolved"), 10);
  const a = async function* () {
    yield "Hello";
    await promise;
    yield "World";
  };
  c.abort();
  const items: string[] = [];
  const error = await assertRejects(
    async () => {
      for await (const item of abortable(a(), c.signal)) {
        items.push(item);
      }
    },
    DOMException,
    "The signal has been aborted",
  );
  assertEquals(error.name, "AbortError");
  assertEquals(items, []);
  await delay(10); // wait for the promise to resolve
});

Deno.test("abortable.AsyncIterable() calls return before throwing", async () => {
  const c = new AbortController();
  let returnCalled = false;
  let timeoutId: number;
  const iterable: AsyncIterable<string> = {
    [Symbol.asyncIterator]: () => ({
      next: () =>
        new Promise((resolve) => {
          timeoutId = setTimeout(
            () => resolve({ value: "Hello", done: false }),
            1,
          );
        }),
      return: () => {
        returnCalled = true;
        clearTimeout(timeoutId);
        return Promise.resolve({ value: undefined, done: true });
      },
    }),
  };
  setTimeout(() => c.abort(), 1);
  const items: string[] = [];
  const error = await assertRejects(
    async () => {
      for await (const item of abortable(iterable, c.signal)) {
        items.push(item);
      }
    },
    DOMException,
    "The signal has been aborted",
  );
  assertEquals(returnCalled, true);
  assertEquals(error.name, "AbortError");
  assertEquals(items, []);
});

Deno.test("abortable.AsyncIterable() behaves just like original when not aborted", async () => {
  async function* gen() {
    yield 1;
    yield await Promise.resolve(2);
    yield 3;
    return 4;
  }
  const normalIterator = gen();
  const abortController = new AbortController();
  const abortableIterator = abortable(gen(), abortController.signal);

  assertEquals(await abortableIterator.next(), await normalIterator.next());
  assertEquals(await abortableIterator.next(), await normalIterator.next());
  assertEquals(await abortableIterator.next(), await normalIterator.next());
  assertEquals(await abortableIterator.next(), await normalIterator.next());
  assertEquals(await abortableIterator.next(), await normalIterator.next());
});

Deno.test("abortable.AsyncIterable() behaves just like original when return is called", async () => {
  async function* gen() {
    yield 1;
    yield await Promise.resolve(2);
    yield 3;
    return 4;
  }
  const normalIterator = gen();
  const abortController = new AbortController();
  const abortableIterator = abortable(gen(), abortController.signal);

  assertEquals(
    await abortableIterator.next(123),
    await normalIterator.next(123),
  );
  assertEquals(
    await abortableIterator.return(321),
    await normalIterator.return(321),
  );
  assertEquals(await abortableIterator.next(), await normalIterator.next());
});
